<?xml version='1.0' encoding='UTF-8'?>
<robot name="XMS5-R800-W4G3B4C">
  <!-- Constants for robot dimensions -->
  <material name="black">
    <color rgba="0.0 0.0 0.0 1.0"/>
  </material>
  <material name="blue">
    <color rgba="0.0 0.0 0.8 1.0"/>
  </material>
  <material name="green">
    <color rgba="0.0 0.8 0.0 1.0"/>
  </material>
  <material name="grey">
    <color rgba="0.2 0.2 0.2 1.0"/>
  </material>
  <material name="orange">
    <color rgba="1.0 0.423529411765 0.0392156862745 1.0"/>
  </material>
  <material name="brown">
    <color rgba="0.870588235294 0.811764705882 0.764705882353 1.0"/>
  </material>
  <material name="red">
    <color rgba="0.8 0.0 0.0 1.0"/>
  </material>
  <material name="white">
    <color rgba="1.0 1.0 1.0 1.0"/>
  </material>
  <material name="Beige">
    <color rgba="1.0 0.784 0.5765 1.0"/>
  </material>
  <!-- Used for fixing robot to Gazebo 'base_link' -->
  <link name="world"/>
  <joint name="fixed" type="fixed">
    <parent link="world"/>
    <child link="XMS5-R800-W4G3B4C_base"/>
  </joint>
  <!--base-->
  <link name="XMS5-R800-W4G3B4C_base">
    <visual>
      <geometry>
        <mesh filename="meshes/xms5_r800_w4g3b4c_meshes/XMS5-R800-W4G3B4C_base.stl" scale="0.001 0.001 0.001"/>
      </geometry>
      <origin rpy="0 0 0" xyz="0.0 0.0 0.0"/>
      <material name="white"/>
    </visual>
    <collision>
      <geometry>
        <mesh filename="meshes/xms5_r800_w4g3b4c_meshes/XMS5-R800-W4G3B4C_base.stl" scale="0.001 0.001 0.001"/>
      </geometry>
      <origin rpy="0 0 0" xyz="0.0 0.0 0.0"/>
    </collision>
  </link>
  <joint name="XMS5-R800-W4G3B4C_joint_1" type="revolute">
    <parent link="XMS5-R800-W4G3B4C_base"/>
    <child link="XMS5-R800-W4G3B4C_link1"/>
    <limit effort="113" lower="-6.2832" upper="6.2832" velocity="3.141592653589793"/>
    <axis xyz="0 0 1"/>
    <origin rpy="0 0 0" xyz="0.0 0.0 0.328"/>
  </joint>
  <transmission name="tran1">
    <type>transmission_interface/SimpleTransmission</type>
    <joint name="XMS5-R800-W4G3B4C_joint_7">
      <hardwareInterface>EffortJointInterface</hardwareInterface>
    </joint>
    <actuator name="motor1">
      <hardwareInterface>EffortJointInterface</hardwareInterface>
      <mechanicalReduction>1</mechanicalReduction>
    </actuator>
  </transmission>
  <!--link 1-->
  <link name="XMS5-R800-W4G3B4C_link1">
    <visual>
      <geometry>
        <mesh filename="meshes/xms5_r800_w4g3b4c_meshes/XMS5-R800-W4G3B4C_link1.stl" scale="0.001 0.001 0.001"/>
      </geometry>
      <origin rpy="0 0 0" xyz="0 0 0"/>
      <material name="white"/>
    </visual>
    <inertial>
      <mass value="3.167"/>
      <inertia ixx="0.03116799" ixy="-0.00000065" ixz="-0.00000427" iyy="0.03071271" iyz="-0.00223656" izz="0.00587740"/>
      <origin rpy="0 0 0" xyz="1.1e-05 -0.007992 0.23584200000000002"/>
    </inertial>
    <collision>
      <geometry>
        <mesh filename="meshes/xms5_r800_w4g3b4c_meshes/XMS5-R800-W4G3B4C_link1.stl" scale="0.001 0.001 0.001"/>
      </geometry>
      <origin rpy="0 0 0" xyz="0 0 0"/>
    </collision>
  </link>
  <joint name="XMS5-R800-W4G3B4C_joint_2" type="revolute">
    <parent link="XMS5-R800-W4G3B4C_link1"/>
    <child link="XMS5-R800-W4G3B4C_link2"/>
    <limit effort="113" lower="-2.7925" upper="2.618" velocity="3.141592653589793"/>
    <axis xyz="0 1 0"/>
    <origin rpy="0 0 0" xyz="0.0 0.0 0.0"/>
  </joint>
  <transmission name="tran2">
    <type>transmission_interface/SimpleTransmission</type>
    <joint name="xmate_joint_2">
      <hardwareInterface>EffortJointInterface</hardwareInterface>
    </joint>
    <actuator name="motor2">
      <hardwareInterface>EffortJointInterface</hardwareInterface>
      <mechanicalReduction>1</mechanicalReduction>
    </actuator>
  </transmission>
  <!--link 2-->
  <link name="XMS5-R800-W4G3B4C_link2">
    <visual>
      <geometry>
        <mesh filename="meshes/xms5_r800_w4g3b4c_meshes/XMS5-R800-W4G3B4C_link2.stl" scale="0.001 0.001 0.001"/>
      </geometry>
      <origin rpy="0 0 0" xyz="0 0 0.0"/>
      <material name="white"/>
    </visual>
    <inertial>
      <mass value="4.291"/>
      <inertia ixx="0.14042515" ixy="0.00039009" ixz="0.01494819" iyy="0.14040198" iyz="-0.00255277" izz="0.01264775"/>
      <origin rpy="0 0 0" xyz="0.016666 -0.069301 0.184671"/>
    </inertial>
    <collision>
      <geometry>
        <mesh filename="meshes/xms5_r800_w4g3b4c_meshes/XMS5-R800-W4G3B4C_link2.stl" scale="0.001 0.001 0.001"/>
      </geometry>
      <origin rpy="0 0 0" xyz="0 0 0.0"/>
    </collision>
  </link>
  <joint name="XMS5-R800-W4G3B4C_joint_3" type="revolute">
    <parent link="XMS5-R800-W4G3B4C_link2"/>
    <child link="XMS5-R800-W4G3B4C_link3"/>
    <limit effort="70" lower="-2.9671" upper="2.4435" velocity="3.141592653589793"/>
    <axis xyz="0 -1 0"/>
    <origin rpy="0 0 0" xyz="0.05 0.0 0.4"/>
  </joint>
  <transmission name="tran3">
    <type>transmission_interface/SimpleTransmission</type>
    <joint name="xmate_joint_3">
      <hardwareInterface>EffortJointInterface</hardwareInterface>
    </joint>
    <actuator name="motor3">
      <hardwareInterface>EffortJointInterface</hardwareInterface>
      <mechanicalReduction>1</mechanicalReduction>
    </actuator>
  </transmission>
  <!--link 3-->
  <link name="XMS5-R800-W4G3B4C_link3">
    <visual>
      <geometry>
        <mesh filename="meshes/xms5_r800_w4g3b4c_meshes/XMS5-R800-W4G3B4C_link3.stl" scale="0.001 0.001 0.001"/>
      </geometry>
      <origin rpy="0 0 0" xyz="0 0 0"/>
      <material name="white"/>
    </visual>
    <inertial>
      <mass value="2.018"/>
      <inertia ixx="0.02103842" ixy="-0.00048390" ixz="0.00402665" iyy="0.02167667" iyz="-0.00170490" izz="0.00429357"/>
      <origin rpy="0 0 0" xyz="0.0249 0.009986 0.08373900000000001"/>
    </inertial>
    <collision>
      <geometry>
        <mesh filename="meshes/xms5_r800_w4g3b4c_meshes/XMS5-R800-W4G3B4C_link3.stl" scale="0.001 0.001 0.001"/>
      </geometry>
      <origin rpy="0 0 0" xyz="0 0 0"/>
    </collision>
  </link>
  <joint name="XMS5-R800-W4G3B4C_joint_4" type="revolute">
    <parent link="XMS5-R800-W4G3B4C_link3"/>
    <child link="XMS5-R800-W4G3B4C_link4"/>
    <limit effort="25" lower="-6.2832" upper="6.2832" velocity="3.141592653589793"/>
    <!--     lower="-6.2832" upper="6.2832" -->
    <axis xyz="0 0 1"/>
    <!--     <origin rpy="0 0 0" xyz=-0.05 0.0 0.4/> -->
    <origin rpy="0 0 0" xyz="-0.05 0.0 0.4"/>
  </joint>
  <transmission name="tran4">
    <type>transmission_interface/SimpleTransmission</type>
    <joint name="xmate_joint_4">
      <hardwareInterface>EffortJointInterface</hardwareInterface>
    </joint>
    <actuator name="motor4">
      <hardwareInterface>EffortJointInterface</hardwareInterface>
      <mechanicalReduction>1</mechanicalReduction>
    </actuator>
  </transmission>
  <!--link 4-->
  <link name="XMS5-R800-W4G3B4C_link4">
    <visual>
      <geometry>
        <mesh filename="meshes/xms5_r800_w4g3b4c_meshes/XMS5-R800-W4G3B4C_link4.stl" scale=".001 0.001 0.001"/>
      </geometry>
      <origin rpy="0 0 0" xyz="0.0 0.0 0.0"/>
      <material name="white"/>
    </visual>
    <inertial>
      <mass value="2.005"/>
      <inertia ixx="0.01325119" ixy="0.00000061" ixz="0.00000278" iyy="0.01255684" iyz="-0.00115731" izz="0.00274485"/>
      <origin rpy="0 0 0" xyz="6.6e-05 -0.008515 -0.068865"/>
    </inertial>
    <collision>
      <geometry>
        <mesh filename="meshes/xms5_r800_w4g3b4c_meshes/XMS5-R800-W4G3B4C_link4.stl" scale="0.001 0.001 0.001"/>
      </geometry>
      <origin rpy="0 0 0" xyz="0.0 0.0 0.0"/>
    </collision>
  </link>
  <joint name="XMS5-R800-W4G3B4C_joint_5" type="revolute">
    <parent link="XMS5-R800-W4G3B4C_link4"/>
    <child link="XMS5-R800-W4G3B4C_link5"/>
    <limit effort="25" lower="-6.2832" upper="6.2832" velocity="3.141592653589793"/>
    <axis xyz="0 -1 0"/>
    <origin rpy="0 0 0" xyz="0.0 0.136 0.0"/>
  </joint>
  <transmission name="tran5">
    <type>transmission_interface/SimpleTransmission</type>
    <joint name="xmate_joint_5">
      <hardwareInterface>EffortJointInterface</hardwareInterface>
    </joint>
    <actuator name="motor5">
      <hardwareInterface>EffortJointInterface</hardwareInterface>
      <mechanicalReduction>1</mechanicalReduction>
    </actuator>
  </transmission>
  <!--link 5-->
  <link name="XMS5-R800-W4G3B4C_link5">
    <visual>
      <geometry>
        <mesh filename="meshes/xms5_r800_w4g3b4c_meshes/XMS5-R800-W4G3B4C_link5.stl" scale="0.001 0.001 0.001"/>
      </geometry>
      <origin rpy="0 0 0" xyz="0 0 0"/>
      <material name="white"/>
    </visual>
    <inertial>
      <mass value="1.507"/>
      <inertia ixx="0.00503262" ixy="-0.00000608" ixz="-0.00000129" iyy="0.00261442" iyz="-0.00033165" izz="0.00394480"/>
      <origin rpy="0 0 0" xyz="3e-06 0.029172999999999998 0.007019"/>
    </inertial>
    <collision>
      <geometry>
        <mesh filename="meshes/xms5_r800_w4g3b4c_meshes/XMS5-R800-W4G3B4C_link5.stl" scale="0.001 0.001 0.001"/>
      </geometry>
      <origin rpy="0 0 0" xyz="0 0 0"/>
    </collision>
  </link>
  <joint name="XMS5-R800-W4G3B4C_joint_6" type="revolute">
    <parent link="XMS5-R800-W4G3B4C_link5"/>
    <child link="XMS5-R800-W4G3B4C_link6"/>
    <limit effort="19" lower="-6.2832" upper="6.2832" velocity="3.141592653589793"/>
    <axis xyz="0 0 1"/>
    <origin rpy="0.0 0.0 0" xyz="0.0 0.0 0.1035"/>
  </joint>
  <transmission name="tran6">
    <type>transmission_interface/SimpleTransmission</type>
    <joint name="xmate_joint_6">
      <hardwareInterface>EffortJointInterface</hardwareInterface>
    </joint>
    <actuator name="motor6">
      <hardwareInterface>EffortJointInterface</hardwareInterface>
      <mechanicalReduction>1</mechanicalReduction>
    </actuator>
  </transmission>
  <!--link 6-->
  <link name="XMS5-R800-W4G3B4C_link6">
    <visual>
      <geometry>
        <mesh filename="meshes/xms5_r800_w4g3b4c_meshes/XMS5-R800-W4G3B4C_link6.stl" scale="0.001 0.001 0.001"/>
      </geometry>
      <origin rpy="0 0 0" xyz="0.0 0.0 0.0"/>
      <material name="white"/>
    </visual>
    <inertial>
      <mass value="0.634"/>
      <inertia ixx="0.00099702" ixy="-0.00000138" ixz="0.00000090" iyy="0.00100253" iyz="0.00000158" izz="0.00044795"/>
      <origin rpy="0 0 0" xyz="7.3e-05 7.9e-05 -0.044853000000000004"/>
    </inertial>
    <collision>
      <geometry>
        <mesh filename="meshes/xms5_r800_w4g3b4c_meshes/XMS5-R800-W4G3B4C_link6.stl" scale="0.001 0.001 0.001"/>
      </geometry>
      <origin rpy="0 0 0" xyz="0.0 0.0 0.0"/>
    </collision>
  </link>
  <link name="tool0"/>
  <joint name="joint_tool0" type="fixed">
    <parent link="XMS5-R800-W4G3B4C_link6"/>
    <child link="tool0"/>
    <origin xyz="0 0 0" rpy="0 0 0"/>
  </joint>
  <link name="tool1">
    <visual>
      <geometry>
        <sphere radius="0.01"/>
      </geometry>
      <origin xyz="0 0 0" rpy="0 0 0"/>
      <material name="red"/>
    </visual>
  </link>
  <joint name="joint_tool1" type="fixed">
    <parent link="tool0"/>
    <child link="tool1"/>
    <origin xyz="-0.01588615307905028 0.018348498948158043 0.2586775713451509" rpy="0.03702517838719945 0.6751675651256659 2.375248653715161"/>
  </joint>
</robot>
